2025-07-29 17:32:02,820 - src.llm.azure_client - INFO - Azure OpenAI client initialized with deployment: gpt-4o-mini
2025-07-29 17:32:04,247 - httpx - INFO - HTTP Request: POST https://fbrdev-ai.openai.azure.com/openai/deployments/gpt-4o-mini/chat/completions?api-version=2024-08-01-preview "HTTP/1.1 403 Forbidden"
2025-07-29 17:32:04,250 - src.llm.azure_client - ERROR - LLM Error: Error code: 403 - {'error': {'code': '403', 'message': 'Access denied due to Virtual Network/Firewall rules.'}}
2025-07-29 17:32:04,251 - src.llm.azure_client - ERROR - Chat failed: Error code: 403 - {'error': {'code': '403', 'message': 'Access denied due to Virtual Network/Firewall rules.'}}
2025-07-29 17:33:24,783 - httpx - INFO - HTTP Request: POST https://fbrdev-ai.openai.azure.com/openai/deployments/gpt-4o-mini/chat/completions?api-version=2024-08-01-preview "HTTP/1.1 403 Forbidden"
2025-07-29 17:33:24,788 - src.llm.azure_client - ERROR - LLM Error: Error code: 403 - {'error': {'code': '403', 'message': 'Access denied due to Virtual Network/Firewall rules.'}}
2025-07-29 17:33:24,789 - src.llm.azure_client - ERROR - Chat failed: Error code: 403 - {'error': {'code': '403', 'message': 'Access denied due to Virtual Network/Firewall rules.'}}
2025-07-29 17:33:36,661 - httpx - INFO - HTTP Request: POST https://fbrdev-ai.openai.azure.com/openai/deployments/gpt-4o-mini/chat/completions?api-version=2024-08-01-preview "HTTP/1.1 403 Forbidden"
2025-07-29 17:33:36,664 - src.llm.azure_client - ERROR - LLM Error: Error code: 403 - {'error': {'code': '403', 'message': 'Access denied due to Virtual Network/Firewall rules.'}}
2025-07-29 17:33:36,665 - src.llm.azure_client - ERROR - Chat failed: Error code: 403 - {'error': {'code': '403', 'message': 'Access denied due to Virtual Network/Firewall rules.'}}
2025-07-29 17:35:16,174 - src.llm.azure_client - INFO - Azure OpenAI client initialized with deployment: gpt-4o-mini
2025-07-29 17:35:17,528 - httpx - INFO - HTTP Request: POST https://fbrdev-ai.openai.azure.com/openai/deployments/gpt-4o-mini/chat/completions?api-version=2024-08-01-preview "HTTP/1.1 403 Forbidden"
2025-07-29 17:35:17,530 - src.llm.azure_client - ERROR - LLM Error: Error code: 403 - {'error': {'code': '403', 'message': 'Access denied due to Virtual Network/Firewall rules.'}}
2025-07-29 17:35:17,530 - src.llm.azure_client - ERROR - Chat failed: Error code: 403 - {'error': {'code': '403', 'message': 'Access denied due to Virtual Network/Firewall rules.'}}
2025-07-29 17:36:11,615 - src.llm.azure_client - INFO - Azure OpenAI client initialized with deployment: gpt-4o-mini
2025-07-29 17:36:12,827 - httpx - INFO - HTTP Request: POST https://fbrdev-ai.openai.azure.com/openai/deployments/gpt-4o-mini/chat/completions?api-version=2024-08-01-preview "HTTP/1.1 403 Forbidden"
2025-07-29 17:36:12,828 - src.llm.azure_client - ERROR - LLM Error: Error code: 403 - {'error': {'code': '403', 'message': 'Access denied due to Virtual Network/Firewall rules.'}}
2025-07-29 17:36:12,828 - src.llm.azure_client - ERROR - Chat failed: Error code: 403 - {'error': {'code': '403', 'message': 'Access denied due to Virtual Network/Firewall rules.'}}
2025-07-29 17:36:28,493 - httpx - INFO - HTTP Request: POST https://fbrdev-ai.openai.azure.com/openai/deployments/gpt-4o-mini/chat/completions?api-version=2024-08-01-preview "HTTP/1.1 403 Forbidden"
2025-07-29 17:36:28,495 - src.llm.azure_client - ERROR - LLM Error: Error code: 403 - {'error': {'code': '403', 'message': 'Access denied due to Virtual Network/Firewall rules.'}}
2025-07-29 17:36:28,495 - src.llm.azure_client - ERROR - Chat failed: Error code: 403 - {'error': {'code': '403', 'message': 'Access denied due to Virtual Network/Firewall rules.'}}
2025-07-29 17:37:35,979 - httpx - INFO - HTTP Request: POST https://fbrdev-ai.openai.azure.com/openai/deployments/gpt-4o-mini/chat/completions?api-version=2024-08-01-preview "HTTP/1.1 403 Forbidden"
2025-07-29 17:59:09,951 - src.llm.azure_client - INFO - Azure OpenAI client initialized with deployment: gpt-4
2025-07-29 17:59:15,326 - src.llm.azure_client - INFO - Azure OpenAI client initialized with deployment: gpt-4o-mini
2025-07-29 17:59:17,336 - httpx - INFO - HTTP Request: POST https://fbrdev-ai.openai.azure.com/openai/deployments/gpt-4o-mini/chat/completions?api-version=2024-08-01-preview "HTTP/1.1 200 OK"
2025-07-29 18:00:59,701 - httpx - INFO - HTTP Request: POST https://fbrdev-ai.openai.azure.com/openai/deployments/gpt-4o-mini/chat/completions?api-version=2024-08-01-preview "HTTP/1.1 200 OK"
2025-07-30 11:12:38,349 - src.llm.azure_client - INFO - Azure OpenAI client initialized with deployment: gpt-4o-mini
2025-07-30 11:12:40,450 - httpx - INFO - HTTP Request: POST https://fbrdev-ai.openai.azure.com/openai/deployments/gpt-4o-mini/chat/completions?api-version=2024-08-01-preview "HTTP/1.1 200 OK"
2025-07-30 11:36:02,540 - src.data.connectors - INFO - Connected to ClickHouse: clickhouse-0-0.umetea.net:443
2025-07-30 11:45:46,762 - urllib3.connectionpool - WARNING - Retrying (Retry(total=0, connect=None, read=None, redirect=0, status=None)) after connection broken by 'SSLError(SSLCertVerificationError(1, '[SSL: CERTIFICATE_VERIFY_FAILED] certificate verify failed: unable to get local issuer certificate (_ssl.c:1010)'))': /?
2025-07-30 11:45:47,366 - clickhouse_connect.driver.httpclient - WARNING - Unexpected Http Driver Exception
2025-07-30 11:45:47,367 - src.data.connectors - ERROR - Failed to connect to ClickHouse: Error HTTPSConnectionPool(host='clickhouse-0-0.umetea.net', port=443): Max retries exceeded with url: /? (Caused by SSLError(SSLCertVerificationError(1, '[SSL: CERTIFICATE_VERIFY_FAILED] certificate verify failed: unable to get local issuer certificate (_ssl.c:1010)'))) executing HTTP request attempt 1 (https://clickhouse-0-0.umetea.net:443)
2025-07-30 11:45:47,367 - src.data.connectors - ERROR - Failed to convert to DataFrame: Cannot connect to ClickHouse: Error HTTPSConnectionPool(host='clickhouse-0-0.umetea.net', port=443): Max retries exceeded with url: /? (Caused by SSLError(SSLCertVerificationError(1, '[SSL: CERTIFICATE_VERIFY_FAILED] certificate verify failed: unable to get local issuer certificate (_ssl.c:1010)'))) executing HTTP request attempt 1 (https://clickhouse-0-0.umetea.net:443)
2025-07-30 11:46:06,806 - src.data.connectors - ERROR - Failed to convert to DataFrame: ClickHouse connection has failed previously
2025-07-30 11:46:24,166 - urllib3.connectionpool - WARNING - Retrying (Retry(total=0, connect=None, read=None, redirect=0, status=None)) after connection broken by 'SSLError(SSLCertVerificationError(1, '[SSL: CERTIFICATE_VERIFY_FAILED] certificate verify failed: unable to get local issuer certificate (_ssl.c:1010)'))': /?
2025-07-30 11:46:24,644 - clickhouse_connect.driver.httpclient - WARNING - Unexpected Http Driver Exception
2025-07-30 11:46:24,644 - src.data.connectors - ERROR - Failed to connect to ClickHouse: Error HTTPSConnectionPool(host='clickhouse-0-0.umetea.net', port=443): Max retries exceeded with url: /? (Caused by SSLError(SSLCertVerificationError(1, '[SSL: CERTIFICATE_VERIFY_FAILED] certificate verify failed: unable to get local issuer certificate (_ssl.c:1010)'))) executing HTTP request attempt 1 (https://clickhouse-0-0.umetea.net:443)
2025-07-30 11:46:24,644 - src.data.connectors - ERROR - Failed to convert to DataFrame: Cannot connect to ClickHouse: Error HTTPSConnectionPool(host='clickhouse-0-0.umetea.net', port=443): Max retries exceeded with url: /? (Caused by SSLError(SSLCertVerificationError(1, '[SSL: CERTIFICATE_VERIFY_FAILED] certificate verify failed: unable to get local issuer certificate (_ssl.c:1010)'))) executing HTTP request attempt 1 (https://clickhouse-0-0.umetea.net:443)
2025-07-30 11:47:15,584 - urllib3.connectionpool - WARNING - Retrying (Retry(total=0, connect=None, read=None, redirect=0, status=None)) after connection broken by 'SSLError(SSLCertVerificationError(1, '[SSL: CERTIFICATE_VERIFY_FAILED] certificate verify failed: unable to get local issuer certificate (_ssl.c:1010)'))': /?
2025-07-30 11:47:16,046 - clickhouse_connect.driver.httpclient - WARNING - Unexpected Http Driver Exception
2025-07-30 11:47:16,046 - src.data.connectors - ERROR - Failed to connect to ClickHouse: Error HTTPSConnectionPool(host='clickhouse-0-0.umetea.net', port=443): Max retries exceeded with url: /? (Caused by SSLError(SSLCertVerificationError(1, '[SSL: CERTIFICATE_VERIFY_FAILED] certificate verify failed: unable to get local issuer certificate (_ssl.c:1010)'))) executing HTTP request attempt 1 (https://clickhouse-0-0.umetea.net:443)
2025-07-30 11:47:16,049 - src.data.connectors - ERROR - Failed to convert to DataFrame: Cannot connect to ClickHouse: Error HTTPSConnectionPool(host='clickhouse-0-0.umetea.net', port=443): Max retries exceeded with url: /? (Caused by SSLError(SSLCertVerificationError(1, '[SSL: CERTIFICATE_VERIFY_FAILED] certificate verify failed: unable to get local issuer certificate (_ssl.c:1010)'))) executing HTTP request attempt 1 (https://clickhouse-0-0.umetea.net:443)
2025-07-30 11:49:06,709 - urllib3.connectionpool - WARNING - Retrying (Retry(total=0, connect=None, read=None, redirect=0, status=None)) after connection broken by 'SSLError(SSLCertVerificationError(1, '[SSL: CERTIFICATE_VERIFY_FAILED] certificate verify failed: unable to get local issuer certificate (_ssl.c:1010)'))': /?
2025-07-30 11:49:07,355 - clickhouse_connect.driver.httpclient - WARNING - Unexpected Http Driver Exception
2025-07-30 11:49:07,357 - src.data.connectors - ERROR - Failed to connect to ClickHouse: Error HTTPSConnectionPool(host='clickhouse-0-0.umetea.net', port=443): Max retries exceeded with url: /? (Caused by SSLError(SSLCertVerificationError(1, '[SSL: CERTIFICATE_VERIFY_FAILED] certificate verify failed: unable to get local issuer certificate (_ssl.c:1010)'))) executing HTTP request attempt 1 (https://clickhouse-0-0.umetea.net:443)
2025-07-30 11:49:07,357 - src.data.connectors - ERROR - Failed to convert to DataFrame: Cannot connect to ClickHouse: Error HTTPSConnectionPool(host='clickhouse-0-0.umetea.net', port=443): Max retries exceeded with url: /? (Caused by SSLError(SSLCertVerificationError(1, '[SSL: CERTIFICATE_VERIFY_FAILED] certificate verify failed: unable to get local issuer certificate (_ssl.c:1010)'))) executing HTTP request attempt 1 (https://clickhouse-0-0.umetea.net:443)
2025-07-30 11:50:49,433 - src.data.connectors - ERROR - Failed to convert to DataFrame: ClickHouse connection has failed previously
2025-07-30 11:54:19,061 - urllib3.connectionpool - WARNING - Retrying (Retry(total=0, connect=None, read=None, redirect=0, status=None)) after connection broken by 'SSLError(SSLCertVerificationError(1, '[SSL: CERTIFICATE_VERIFY_FAILED] certificate verify failed: unable to get local issuer certificate (_ssl.c:1010)'))': /?
2025-07-30 11:54:19,597 - clickhouse_connect.driver.httpclient - WARNING - Unexpected Http Driver Exception
2025-07-30 11:54:19,598 - src.data.connectors - ERROR - Failed to connect to ClickHouse: Error HTTPSConnectionPool(host='clickhouse-0-0.umetea.net', port=443): Max retries exceeded with url: /? (Caused by SSLError(SSLCertVerificationError(1, '[SSL: CERTIFICATE_VERIFY_FAILED] certificate verify failed: unable to get local issuer certificate (_ssl.c:1010)'))) executing HTTP request attempt 1 (https://clickhouse-0-0.umetea.net:443)
2025-07-30 11:54:19,599 - src.data.connectors - ERROR - Failed to convert to DataFrame: Cannot connect to ClickHouse: Error HTTPSConnectionPool(host='clickhouse-0-0.umetea.net', port=443): Max retries exceeded with url: /? (Caused by SSLError(SSLCertVerificationError(1, '[SSL: CERTIFICATE_VERIFY_FAILED] certificate verify failed: unable to get local issuer certificate (_ssl.c:1010)'))) executing HTTP request attempt 1 (https://clickhouse-0-0.umetea.net:443)
2025-07-30 11:55:27,880 - src.data.connectors - ERROR - Failed to connect to ClickHouse: HttpClient.__init__() got an unexpected keyword argument 'verify_ssl'
2025-07-30 11:55:27,880 - src.data.connectors - ERROR - Failed to convert to DataFrame: Cannot connect to ClickHouse: HttpClient.__init__() got an unexpected keyword argument 'verify_ssl'
2025-07-30 11:55:50,227 - src.data.connectors - ERROR - Failed to connect to ClickHouse: HttpClient.__init__() got an unexpected keyword argument 'verify_ssl'
2025-07-30 11:55:50,227 - src.data.connectors - ERROR - Failed to convert to DataFrame: Cannot connect to ClickHouse: HttpClient.__init__() got an unexpected keyword argument 'verify_ssl'
2025-07-30 11:56:14,514 - src.data.connectors - INFO - Connected to ClickHouse using clickhouse_connect: clickhouse-0-0.umetea.net:443
